Workbook

Sheet Datos Tweenvest
B1: CUENTA DE RESULTADOS
B2: Periodo fiscal | C2: 2018 FY | D2: 2019 FY | E2: 2020 FY | F2: 2021 FY | G2: 2022 FY | H2: 2023 FY | I2: 2024 FY
B3: Fecha de cierre | C3: 43190 | D3: 43555 | E3: 43921 | F3: 44286 | G3: 44651 | H3: 45016 | I3: 45382
B4: Divisa | C4: USD | D4: USD | E4: USD | F4: USD | G4: USD | H4: USD | I4: USD
B5: Ventas totales | C5: 1903339000 | D5: 2020437000 | E5: 2132689000 | F5: 2545641000 | G5: 3150339000 | H5: 3627286000 | I5: 4287763000
B6: Coste de ventas | C6: -971697000 | D6: -980187000 | E6: -1029016000 | F6: -1171551000 | G6: -1542788000 | H6: -1801916000 | I6: -1902275000
B7: Coste de los bienes vendidos | C7: -971697000 | D7: -980187000 | E7: -1029016000 | F7: -1171551000 | G7: -1542788000 | H7: -1801916000 | I7: -1902275000
B8: Beneficio bruto | C8: 931642000 | D8: 1040250000 | E8: 1103673000 | F8: 1374090000 | G8: 1607551000 | H8: 1825370000 | I8: 2385488000
B9: Gastos operativos totales | C9: -704974000 | D9: -714143000 | E9: -764501000 | F9: -852546000 | G9: -1039658000 | H9: -1169802000 | I9: -1448795000
B10: Gastos en VG&A | C10: -682602000 | D10: -690956000 | E10: -736946000 | F10: -823920000 | G10: -1006314000 | H10: -1131145000 | I10: -1399624000
B11: Gastos de I+D | C11: -22372000 | D11: -23187000 | E11: -27555000 | F11: -28626000 | G11: -33344000 | H11: -38657000 | I11: -49171000
B12: Beneficio operativo | C12: 226668000 | D12: 326107000 | E12: 339172000 | F12: 521544000 | G12: 567893000 | H12: 655568000 | I12: 936693000
B13: Gastos no operativos totales | C13: -1888000 | D13: 3007000 | E13: 3059000 | F13: -2424000 | G13: -69000 | H13: 13331000 | I13: 51427000
B14: Gastos por intereses | C14: -4585000 | D14: -4661000 | E14: -5046000 | F14: -6028000 | G14: -2083000 | H14: -3442000 | I14: -2564000
B15: Ingresos por int. e inversiones | C15: 3057000 | D15: 6028000 | E15: 7261000 | F15: 2637000 | G15: 1901000 | H15: 15563000 | I15: 52208000
B16: Otros ingresos y gastos no operativos | C16: -360000 | D16: 1640000 | E16: 844000 | F16: 967000 | G16: 113000 | H16: 1210000 | I16: 1783000
... B18: Ítems inusuales totales | C18: -4084000 | D18: -180000 | E18: -1365000 | F18: -17606000 | G18: -3186000 | H18: -2817000 | I18: -9179000
B19: Cargos de fusión y reestructuración | C19: -1667000
B20: Reducción de valor de activos | C20: -2417000 | D20: -180000 | E20: -1365000 | F20: -17606000 | G20: -3186000 | H20: -2817000 | I20: -9179000
B21: EBT incluyendo ítems inusuales | C21: 220696000 | D21: 328934000 | E21: 340866000 | F21: 501514000 | G21: 564638000 | H21: 666082000 | I21: 978941000
B22: Gastos por impuestos | C22: -106302000 | D22: -64626000 | E22: -64724000 | F22: -118939000 | G22: -112689000 | H22: -149260000 | I22: -219378000
B23: Beneficios de operaciones continuas | C23: 114394000 | D23: 264308000 | E23: 276142000 | F23: 382575000 | G23: 451949000 | H23: 516822000 | I23: 759563000
B24: Beneficio neto total | C24: 114394000 | D24: 264308000 | E24: 276142000 | F24: 382575000 | G24: 451949000 | H24: 516822000 | I24: 759563000
B25: Beneficio neto | C25: 114394000 | D25: 264308000 | E25: 276142000 | F25: 382575000 | G25: 451949000 | H25: 516822000 | I25: 759563000
B26: Beneficio neto comunes incl. ítems extra | C26: 114394000 | D26: 264308000 | E26: 276142000 | F26: 382575000 | G26: 451949000 | H26: 516822000 | I26: 759563000
B27: Beneficio neto comunes excl. ítems extra | C27: 114394000 | D27: 264308000 | E27: 276142000 | F27: 382575000 | G27: 451949000 | H27: 516822000 | I27: 759563000
B28: EBITDAR | C28: 350695000 | D28: 445133000 | E28: 466378000 | F28: 641971000 | G28: 689590000 | H28: 792425000 | I28: 1105832000
B29: EBITDA | C29: 275240000 | D29: 371048000 | E29: 378084000 | F29: 562074000 | G29: 610771000 | H29: 703426000 | I29: 994280000
B30: EBITA | C30: 226668000 | D30: 332342000 | E30: 342642000 | F30: 524109000 | G30: 570141000 | H30: 658309000 | I30: 939322000
B31: EBIT | C31: 226668000 | D31: 326107000 | E31: 339172000 | F31: 521544000 | G31: 567893000 | H31: 655568000 | I31: 936693000
B35: BALANCE DE SITUACIÓN
B36: Periodo fiscal | C36: 2018 FY | D36: 2019 FY | E36: 2020 FY | F36: 2021 FY | G36: 2022 FY | H36: 2023 FY | I36: 2024 FY
B37: Fecha de cierre | C37: 43190 | D37: 43555 | E37: 43921 | F37: 44286 | G37: 44651 | H37: 45016 | I37: 45382
B38: Divisa | C38: USD | D38: USD | E38: USD | F38: USD | G38: USD | H38: USD | I38: USD
B39: Efectivo e inv. a CP, Total | C39: 429970000 | D39: 589692000 | E39: 649436000 | F39: 1089361000 | G39: 843527000 | H39: 981795000 | I39: 1502051000
B40: Efectivo y equivalentes | C40: 429970000 | D40: 589692000 | E40: 649436000 | F40: 1089361000 | G40: 843527000 | H40: 981795000 | I40: 1502051000
B41: Cuentas por cobrar, Total | C41: 145880000 | D41: 191383000 | E41: 193747000 | F41: 222028000 | G41: 320931000 | H41: 306295000 | I41: 340124000
B42: Cuentas por cobrar | C42: 143704000 | D42: 189043000 | E42: 185596000 | F42: 215718000 | G42: 302688000 | H42: 301511000 | I42: 296565000
B43: Otras cuentas por cobrar | C43: 2176000 | D43: 2340000 | E43: 8151000 | F43: 6310000 | G43: 18243000 | H43: 4784000 | I43: 43559000
B44: Inventario | C44: 299602000 | D44: 278842000 | E44: 311620000 | F44: 278242000 | G44: 506796000 | H44: 532852000 | I44: 474311000
...

Sheet 1.Income statement
C8: 2018 | D8: 2019 | E8: 2020 | F8: 2021 | G8: 2022 | H8: 2023 | I8: 2024 | J8: 2025 | K8: 2026 | L8: 2027 | M8: 2028 | N8: 2029
B9: Income Statement (millons ,excepto EPS)
B10: Sales | C10: ='Datos Tweenvest'!C5 -> 1903339000 | D10: ='Datos Tweenvest'!D5 -> 2020437000 | E10: ='Datos Tweenvest'!E5 -> 2132689000 | F10: ='Datos Tweenvest'!F5 -> 2545641000 | G10: ='Datos Tweenvest'!G5 -> 3150339000 | H10: ='Datos Tweenvest'!H5 -> 3627286000 | I10: ='Datos Tweenvest'!I5 -> 4287763000 | J10: =(I10*$P$11)+I10 -> 4502151150 | K10: =(J10*$P$11)+J10 -> 4.7272587e+09 | L10: =(K10*$P$11)+K10 -> 4.9636216e+09 | M10: =(L10*$P$11)+L10 -> 5.2118027e+09 | N10: =(M10*$P$11)+M10 -> 5.4723929e+09
B11: Y/Y Growth % | C11: =(C10-B10)/B10 -> #VALUE! | D11: =(D10-C10)/C10 -> 0.061522409 | E11: =(E10-D10)/D10 -> 0.055558278 | F11: =(F10-E10)/E10 -> 0.19362973 | G11: =(G10-F10)/F10 -> 0.23754253 | H11: =(H10-G10)/G10 -> 0.15139545 | I11: =(I10-H10)/H10 -> 0.18208572 | J11: =$P$11 -> 0.05 | K11: =$P$11 -> 0.05 | L11: =$P$11 -> 0.05 | M11: =$P$11 -> 0.05 | N11: =$P$11 -> 0.05 | O11: CRECIMIENTO | P11: 0.05
B12: EBITDA | C12: =C15+C14 -> 275240000 | D12: =D15+D14 -> 371048000 | E12: =E15+E14 -> 378084000 | F12: =F15+F14 -> 562074000 | G12: =G15+G14 -> 610771000 | H12: =H15+H14 -> 703426000 | I12: =I15+I14 -> 994280000 | J12: =J15+J14 -> 6.9076751e+08 | ... N12: =N15+N14 -> 8.3963223e+08
B13: EBITDA margin % | C13: =(C12/C10) -> 0.14460903 | D13: =(D12/D10) -> 0.1836474 | E13: =(E12/E10) -> 0.17728042 | F13: =(F12/F10) -> 0.22079861 | G13: =(G12/G10) -> 0.19387469 | H13: =(H12/H10) -> 0.19392626 | I13: =(I12/I10) -> 0.23188782 | J13: =J12/J10 -> 0.15343055 | K13: =K12/K10 -> 0.15343055 | L13: =L12/L10 -> 0.15343055 | M13: =M12/M10 -> 0.15343055 | N13: =N12/N10 -> 0.15343055
B14: Depreciation & Amortization Expense | C14: ='Datos Tweenvest'!C98 -> 48572000 | D14: ='Datos Tweenvest'!D98 -> 44941000 | E14: ='Datos Tweenvest'!E98 -> 38912000 | F14: ='Datos Tweenvest'!F98 -> 40530000 | G14: ='Datos Tweenvest'!G98 -> 42878000 | H14: ='Datos Tweenvest'!H98 -> 47858000 | I14: ='Datos Tweenvest'!I98 -> 57587000 | J14: =(I14*$P$11)+I14 -> 60466350 | K14: =(J14*$P$11)+J14 -> 63489668 | L14: =(K14*$P$11)+K14 -> 66664151 | M14: =(L14*$P$11)+L14 -> 69997358 | N14: =(M14*$P$11)+M14 -> 73497226
B15: EBIT | C15: ='Datos Tweenvest'!C12 -> 226668000 | D15: ='Datos Tweenvest'!D12 -> 326107000 | E15: ='Datos Tweenvest'!E12 -> 339172000 | F15: ='Datos Tweenvest'!F12 -> 521544000 | G15: ='Datos Tweenvest'!G12 -> 567893000 | H15: ='Datos Tweenvest'!H12 -> 655568000 | I15: ='Datos Tweenvest'!I12 -> 936693000 | J15: =J10*$P$16 -> 6.3030116e+08 | K15: =K10*$P$16 -> 6.6181622e+08 | L15: =L10*$P$16 -> 6.9490703e+08 | M15: =M10*$P$16 -> 7.2965238e+08 | N15: =N10*$P$16 -> 7.66135e+08
B16: EBIT margin % | C16: =(C15/C10) -> 0.11908966 | D16: =(D15/D10) -> 0.16140419 | E16: =(E15/E10) -> 0.15903491 | F16: =(F15/F10) -> 0.20487728 | G16: =(G15/G10) -> 0.18026409 | H16: =(H15/H10) -> 0.18073237 | I16: =(I15/I10) -> 0.21845727 | J16: =(J15/J10) -> 0.14 | ... N16: =(N15/N10) -> 0.14 | O16: MARGEN EBIT | P16: 0.14
B17: Interest expense/ Income (introducir en negativo si es un ingreso) | C17: =-'Datos Tweenvest'!C14 -> 4585000 | D17: =-'Datos Tweenvest'!D14 -> 4661000 | E17: =-'Datos Tweenvest'!E14 -> 5046000 | F17: =-'Datos Tweenvest'!F14 -> 6028000 | G17: =-'Datos Tweenvest'!G14 -> 2083000 | H17: =-'Datos Tweenvest'!H14 -> 3442000 | I17: =-'Datos Tweenvest'!I14 -> 2564000 | J17: =(I17*$P$11)+I17 -> 2692200 | K17: =(J17*$P$11)+J17 -> 2826810 | L17: =(K17*$P$11)+K17 -> 2968150.5 | M17: =(L17*$P$11)+L17 -> 3116558 | N17: =(M17*$P$11)+M17 -> 3272385.9
B19: Pretax Income | C19: =C15-C17 -> 222083000 | D19: =D15-D17 -> 321446000 | E19: =E15-E17 -> 334126000 | F19: =F15-F17-F18 -> 515516000 | G19: =G15-G17 -> 565810000 | H19: =H15-H17 -> 652126000 | I19: =I15-I17 -> 934129000 | J19: =J15-J17-J18 -> 6.2760896e+08 | K19: =K15-K17-K18 -> 6.5898941e+08 | L19: =L15-L17-L18 -> 6.9193888e+08 | M19: =M15-M17-M18 -> 7.2653582e+08 | N19: =N15-N17-N18 -> 7.6286261e+08
B20: Income Taxes | C20: =-'Datos Tweenvest'!C22 -> 106302000 | D20: =-'Datos Tweenvest'!D22 -> 64626000 | E20: =-'Datos Tweenvest'!E22 -> 64724000 | F20: =-'Datos Tweenvest'!F22 -> 118939000 | G20: =-'Datos Tweenvest'!G22 -> 112689000 | H20: =-'Datos Tweenvest'!H22 -> 149260000 | I20: =-'Datos Tweenvest'!I22 -> 219378000 | J20: =J19*J21 -> 1.5690224e+08 | K20: =K19*K21 -> 1.6474735e+08 | L20: =L19*L21 -> 1.7298472e+08 | M20: =M19*M21 -> 1.8163396e+08 | N20: =N19*N21 -> 1.9071565e+08
B21: tax rate | C21: =(C20/C19) -> 0.47865888 | D21: =(D20/D19) -> 0.20104777 | E21: =(E20/E19) -> 0.19371135 | F21: =(F20/F19) -> 0.23071835 | G21: =(G20/G19) -> 0.19916403 | H21: =(H20/H19) -> 0.22888215 | I21: =(I20/I19) -> 0.23484765 | J21: =$P$21 -> 0.25 | K21: =$P$21 -> 0.25 | L21: =$P$21 -> 0.25 | M21: =$P$21 -> 0.25 | N21: =$P$21 -> 0.25 | O21: TAX RATE | P21: 0.25
B22: Consolidated Net Income | C22: =C19-C20 -> 115781000 | D22: =D19-D20 -> 256820000 | E22: =E19-E20 -> 269402000 | F22: =F19-F20 -> 396577000 | G22: =G19-G20 -> 453121000 | H22: =H19-H20 -> 502866000 | I22: =I19-I20 -> 714751000 | J22: =J19-J20 -> 4.7070672e+08 | ... N22: =N19-N20 -> 5.7214696e+08
B23: Minority Interest | C23: 0 | D23: 0 | E23: 0 | F23: 0 | G23: 0 | H23: 0 | I23: 0 | J23: =I23*(1+$P$11) -> 0 | K23: =J23*(1+$P$11) -> 0 | L23: =K23*(1+$P$11) -> 0 | M23: =L23*(1+$P$11) -> 0 | N23: =M23*(1+$P$11) -> 0
B24: Net Income | C24: =C22-C23 -> 115781000 | D24: =D22-D23 -> 256820000 | E24: =E22-E23 -> 269402000 | F24: =F22-F23 -> 396577000 | G24: =G22-G23 -> 453121000 | H24: =H22-H23 -> 502866000 | I24: =I22-I23 -> 714751000 | J24: =J22-J23 -> 4.7070672e+08 | ... N24: =N22-N23 -> 5.7214696e+08
B25: Margen beneficio neto % | C25: =C24/C10 -> 0.060830467 | D25: =D24/D10 -> 0.12711112 | E25: =E24/E10 -> 0.12632034 | F25: =F24/F10 -> 0.1557867 | G25: =G24/G10 -> 0.14383246 | H25: =H24/H10 -> 0.13863423 | I25: =I24/I10 -> 0.16669555 | J25: =J24/J10 -> 0.10455151 | ... N25: =N24/N10 -> 0.10455151
B26: Net income per share ( EPS ) | C26: =C24/C27 -> 0.60310143 | D26: =D24/D27 -> 1.431406 | E26: =E24/E27 -> 1.5647987 | F26: =F24/F27 -> 2.3268382 | G26: =G24/G27 -> 2.7176281 | H26: =H24/H27 -> 3.1406355 | I26: =I24/I27 -> 4.5732942 | J26: =J24/J27 -> 3.0656528 | ... N26: =N24/N27 -> 4.0544706
B27: Fully diluted shares (millions) | C27: ='Datos Tweenvest'!C143 -> 191976000 | D27: ='Datos Tweenvest'!D143 -> 179418000 | E27: ='Datos Tweenvest'!E143 -> 172164000 | F27: ='Datos Tweenvest'!F143 -> 170436000 | G27: ='Datos Tweenvest'!G143 -> 166734000 | H27: ='Datos Tweenvest'!H143 -> 160116000 | I27: ='Datos Tweenvest'!I143 -> 156288000 | J27: =I27-'2.Flujos de caja'!J30 -> 1.5354208e+08 | K27: =J27-'2.Flujos de caja'!K30 -> 1.5065887e+08 | L27: =K27-'2.Flujos de caja'!L30 -> 1.476315e+08 | M27: =L27-'2.Flujos de caja'!M30 -> 1.4445276e+08 | N27: =M27-'2.Flujos de caja'!N30 -> 1.4111508e+08

Sheet 2.Flujos de caja
C8: 2018 | D8: 2019 | E8: 2020 | F8: 2021 | G8: 2022 | H8: 2023 | I8: 2024 | J8: 2025 | K8: 2026 | L8: 2027 | M8: 2028 | N8: 2029
B9: Cash flow Statement (millones ,excepto EPS)
B10: EBITDA | C10: ='1.Income statement'!C12 -> 275240000 | D10: ='1.Income statement'!D12 -> 371048000 | E10: ='1.Income statement'!E12 -> 378084000 | F10: ='1.Income statement'!F12 -> 562074000 | G10: ='1.Income statement'!G12 -> 610771000 | H10: ='1.Income statement'!H12 -> 703426000 | I10: ='1.Income statement'!I12 -> 994280000 | J10: ='1.Income statement'!J12 -> 6.9076751e+08 | ... N10: ='1.Income statement'!N12 -> 8.3963223e+08
B11: Capex (introducir manual) | C11: =-'Datos Tweenvest'!C116 -> 34813000 | D11: =-'Datos Tweenvest'!D116 -> 29086000 | E11: =-'Datos Tweenvest'!E116 -> 32455000 | F11: =-'Datos Tweenvest'!F116 -> 32218000 | G11: =-'Datos Tweenvest'!G116 -> 51017000 | H11: =-'Datos Tweenvest'!H116 -> 81025000 | I11: =-'Datos Tweenvest'!I116 -> 89365000 | J11: =(I11*'1.Income statement'!$P$11)+I11 -> 93833250 | K11: =(J11*'1.Income statement'!$P$11)+J11 -> 98524912 | L11: =(K11*'1.Income statement'!$P$11)+K11 -> 1.0345116e+08 | M11: =(L11*'1.Income statement'!$P$11)+L11 -> 1.0862372e+08 | N11: =(M11*'1.Income statement'!$P$11)+M11 -> 1.140549e+08
B12: Ajuste leases | C12: 0 | D12: 0 | E12: 0 | F12: 0 | G12: 0 | H12: 0 | I12: 0 | J12: =(I12*'1.Income statement'!$P$11)+I12 -> 0 | K12: =(J12*'1.Income statement'!$P$11)+J12 -> 0 | L12: =(K12*'1.Income statement'!$P$11)+K12 -> 0 | M12: =(L12*'1.Income statement'!$P$11)+L12 -> 0 | N12: =(M12*'1.Income statement'!$P$11)+M12 -> 0
B13: Intereses | C13: ='1.Income statement'!C17 -> 4585000 | D13: ='1.Income statement'!D17 -> 4661000 | E13: ='1.Income statement'!E17 -> 5046000 | F13: ='1.Income statement'!F17 -> 6028000 | G13: ='1.Income statement'!G17 -> 2083000 | H13: ='1.Income statement'!H17 -> 3442000 | I13: ='1.Income statement'!I17 -> 2564000 | J13: ='1.Income statement'!J17 -> 2692200 | ... N13: ='1.Income statement'!N17 -> 3272385.9
B14: Tasas | C14: ='1.Income statement'!C20 -> 106302000 | D14: ='1.Income statement'!D20 -> 64626000 | E14: ='1.Income statement'!E20 -> 64724000 | F14: ='1.Income statement'!F20 -> 118939000 | G14: ='1.Income statement'!G20 -> 112689000 | H14: ='1.Income statement'!H20 -> 149260000 | I14: ='1.Income statement'!I20 -> 219378000 | J14: ='1.Income statement'!J20 -> 1.5690224e+08 | ... N14: ='1.Income statement'!N20 -> 1.9071565e+08
B15: Minoritarios (si procede) | C15: ='1.Income statement'!C23 -> 0 | D15: ='1.Income statement'!D23 -> 0 | E15: ='1.Income statement'!E23 -> 0 | F15: ='1.Income statement'!F23 -> 0 | G15: ='1.Income statement'!G23 -> 0 | H15: ='1.Income statement'!H23 -> 0 | I15: ='1.Income statement'!I23 -> 0 | J15: ='1.Income statement'!J23 -> 0 | ... N15: ='1.Income statement'!N23 -> 0
B16: Flujo de caja libre | C16: =C10-C11-C13-C14-C15-C12 -> 129540000 | D16: =D10-D11-D13-D14-D15-D12 -> 272675000 | E16: =E10-E11-E13-E14-E15-E12 -> 275859000 | F16: =F10-F11-F13-F14-F15-F12 -> 404889000 | G16: =G10-G11-G13-G14-G15-G12 -> 444982000 | H16: =H10-H11-H13-H14-H15-H12 -> 469699000 | I16: =I10-I11-I13-I14-I15-I12 -> 682973000 | J16: =J10-J11-J13-J14-J15-J12 -> 4.3733982e+08 | ... N16: =N10-N11-N13-N14-N15-N12 -> 5.3158929e+08
B17: Flujo de caja libre por accion | C17: =C16/'1.Income statement'!C27 -> 0.67477185 | D17: =D16/'1.Income statement'!D27 -> 1.5197751 | E17: =E16/'1.Income statement'!E27 -> 1.6023036 | F17: =F16/'1.Income statement'!F27 -> 2.3756073 | G17: =G16/'1.Income statement'!G27 -> 2.6688138 | H17: =H16/'1.Income statement'!H27 -> 2.933492 | I17: =I16/'1.Income statement'!I27 -> 4.3699644 | J17: =J16/'1.Income statement'!J27 -> 2.8483384 | ... N17: =N16/'1.Income statement'!N27 -> 3.7670621
J21: 2025 | K21: 2026 | L21: 2027 | M21: 2028 | N21: 2029
I22: Caja | J22: =J16 -> 4.3733982e+08 | K22: =K16 -> 4.5920681e+08 | L22: =L16 -> 4.8216715e+08 | M22: =M16 -> 5.0627551e+08 | N22: =N16 -> 5.3158929e+08
I23: Número de acciones | J23: ='1.Income statement'!I27 -> 156288000 | K23: ='1.Income statement'!J27 -> 1.5354208e+08 | L23: ='1.Income statement'!K27 -> 1.5065887e+08 | M23: ='1.Income statement'!L27 -> 1.476315e+08 | N23: ='1.Income statement'!M27 -> 1.4445276e+08
I24: Precio | J24: ='4. Valoración'!Q9 -> 82.82 | K24: 82.82 | L24: 82.82 | M24: 82.82 | N24: 82.82
I26: porcentaje de recompra | J26: =52% -> 0.52 | K26: 0.52 | L26: 0.52 | M26: 0.52 | N26: 0.52
I28: Cuanta caja en recompras | J28: =J26*J22 -> 2.2741671e+08 | K28: =K26*K22 -> 2.3878754e+08 | L28: =L26*L22 -> 2.5072692e+08 | M28: =M26*M22 -> 2.6326327e+08 | N28: =N26*N22 -> 2.7642643e+08
I30: Cuantas acciones recompran | J30: =J28/J24 -> 2745915.3 | K30: =K28/K24 -> 2883211.1 | L30: =L28/L24 -> 3027371.6 | M30: =M28/M24 -> 3178740.2 | N30: =N28/N24 -> 3337677.2
I31: Caja restante | J31: =J22-J28 -> 2.0992311e+08 | K31: =K22-K28 -> 2.2041927e+08 | L31: =L22-L28 -> 2.3144023e+08 | M31: =M22-M28 -> 2.4301224e+08 | N31: =N22-N28 -> 2.5516286e+08

Sheet 3.retornos capital
C8: 2018 | D8: 2019 | E8: 2020 | F8: 2021 | G8: 2022 | H8: 2023 | I8: 2024 | J8: 2025 | K8: 2026 | L8: 2027 | M8: 2028 | N8: 2029
B9: Retornos capital (millones ,excepto EPS)
B10: EBIT | C10: ='1.Income statement'!C15 -> 226668000 | D10: ='1.Income statement'!D15 -> 326107000 | E10: ='1.Income statement'!E15 -> 339172000 | F10: ='1.Income statement'!F15 -> 521544000 | G10: ='1.Income statement'!G15 -> 567893000 | H10: ='1.Income statement'!H15 -> 655568000 | I10: ='1.Income statement'!I15 -> 936693000 | J10: ='1.Income statement'!J15 -> 6.3030116e+08 | ... N10: ='1.Income statement'!N15 -> 7.66135e+08 | O10: CRECIMIENTO | P10: ='1.Income statement'!P11 -> 0.05
B11: Interest | C11: ='1.Income statement'!C17 -> 4585000 | D11: ='1.Income statement'!D17 -> 4661000 | E11: ='1.Income statement'!E17 -> 5046000 | F11: ='1.Income statement'!F17 -> 6028000 | G11: ='1.Income statement'!G17 -> 2083000 | H11: ='1.Income statement'!H17 -> 3442000 | I11: ='1.Income statement'!I17 -> 2564000 | J11: ='1.Income statement'!J17 -> 2692200 | ... N11: ='1.Income statement'!N17 -> 3272385.9
B12: Tasas | C12: ='1.Income statement'!C20 -> 106302000 | D12: ='1.Income statement'!D20 -> 64626000 | E12: ='1.Income statement'!E20 -> 64724000 | F12: ='1.Income statement'!F20 -> 118939000 | G12: ='1.Income statement'!G20 -> 112689000 | H12: ='1.Income statement'!H20 -> 149260000 | I12: ='1.Income statement'!I20 -> 219378000 | J12: ='1.Income statement'!J20 -> 1.5690224e+08 | ... N12: ='1.Income statement'!N20 -> 1.9071565e+08
B13: Net income | C13: ='1.Income statement'!C24 -> 115781000 | D13: ='1.Income statement'!D24 -> 256820000 | E13: ='1.Income statement'!E24 -> 269402000 | F13: ='1.Income statement'!F24 -> 396577000 | G13: ='1.Income statement'!G24 -> 453121000 | H13: ='1.Income statement'!H24 -> 502866000 | I13: ='1.Income statement'!I24 -> 714751000 | J13: ='1.Income statement'!J24 -> 4.7070672e+08 | ... N13: ='1.Income statement'!N24 -> 5.7214696e+08
B14: (+) Cash and cash equivalents | C14: ='Datos Tweenvest'!C39 -> 429970000 | D14: ='Datos Tweenvest'!D39 -> 589692000 | E14: ='Datos Tweenvest'!E39 -> 649436000 | F14: ='Datos Tweenvest'!F39 -> 1089361000 | G14: ='Datos Tweenvest'!G39 -> 843527000 | H14: ='Datos Tweenvest'!H39 -> 981795000 | I14: ='Datos Tweenvest'!I39 -> 1502051000 | J14: =I14*$P$10+I14 -> 1577153550 | K14: =J14*$P$10+J14 -> 1.6560112e+09 | L14: =K14*$P$10+K14 -> 1.7388118e+09 | M14: =L14*$P$10+L14 -> 1.8257524e+09 | N14: =M14*$P$10+M14 -> 1.91704e+09
B15: (+) Deuda financiera total | C15: ='Datos Tweenvest'!C83 -> 32082000 | D15: ='Datos Tweenvest'!D83 -> 31504000 | E15: ='Datos Tweenvest'!E83 -> 295716000 | F15: ='Datos Tweenvest'!F83 -> 223042000 | G15: ='Datos Tweenvest'!G83 -> 222070000 | H15: ='Datos Tweenvest'!H83 -> 246488000 | I15: ='Datos Tweenvest'!I83 -> 266879000 | J15: =I15*$P$10+I15 -> 280222950 | K15: =J15*$P$10+J15 -> 2.942341e+08 | L15: =K15*$P$10+K15 -> 3.089458e+08 | M15: =L15*$P$10+L15 -> 3.2439309e+08 | N15: =M15*$P$10+M15 -> 3.4061275e+08
B16: (+) Deuda leases | C16: 0 | D16: 0 | E16: 0 | F16: 0 | G16: 0 | H16: 0 | I16: 0 | J16: =I16*$P$10+I16 -> 0 | K16: =J16*$P$10+J16 -> 0 | L16: =K16*$P$10+K16 -> 0 | M16: =L16*$P$10+L16 -> 0 | N16: =M16*$P$10+M16 -> 0
B17: (+) Goodwill | C17: ='Datos Tweenvest'!C52 -> 13990000 | D17: ='Datos Tweenvest'!D52 -> 13990000 | E17: ='Datos Tweenvest'!E52 -> 13990000 | F17: ='Datos Tweenvest'!F52 -> 13990000 | G17: ='Datos Tweenvest'!G52 -> 13990000 | H17: ='Datos Tweenvest'!H52 -> 13990000 | I17: ='Datos Tweenvest'!I52 -> 13990000 | J17: =I17*$P$10+I17 -> 14689500 | K17: =J17*$P$10+J17 -> 15423975 | L17: =K17*$P$10+K17 -> 16195174 | M17: =L17*$P$10+L17 -> 17004932 | N17: =M17*$P$10+M17 -> 17855179
B18: (+) Equity | C18: ='Datos Tweenvest'!C80 -> 940779000 | D18: ='Datos Tweenvest'!D80 -> 1045130000 | E18: ='Datos Tweenvest'!E80 -> 1140120000 | F18: ='Datos Tweenvest'!F80 -> 1444225000 | G18: ='Datos Tweenvest'!G80 -> 1538825000 | H18: ='Datos Tweenvest'!H80 -> 1765733000 | I18: ='Datos Tweenvest'!I80 -> 2107468000 | J18: =I18*$P$10+I18 -> 2212841400 | K18: =J18*$P$10+J18 -> 2323483470 | L18: =K18*$P$10+K18 -> 2.4396576e+09 | M18: =L18*$P$10+L18 -> 2.5616405e+09 | N18: =M18*$P$10+M18 -> 2.6897226e+09
B19: Capital empleado con goodwill | C19: =C18+C15-C14+C16 -> 542891000 | D19: =D18+D15-D14+D16 -> 486942000 | E19: =E18+E15-E14+E16 -> 786400000 | F19: =F18+F15-F14+F16 -> 577906000 | G19: =G18+G15-G14+G16 -> 917368000 | H19: =H18+H15-H14+H16 -> 1030426000 | I19: =I18+I15-I14+I16 -> 872296000 | J19: =J18+J15-J14+J16 -> 915910800 | ... N19: =N18+N15-N14+N16 -> 1.1132953e+09
B20: Capital empleado sin goodwill | C20: =C15-C14+C18-C17+C16 -> 528901000 | D20: =D15-D14+D18-D17+D16 -> 472952000 | E20: =E15-E14+E18-E17+E16 -> 772410000 | F20: =F15-F14+F18-F17+F16 -> 563916000 | G20: =G15-G14+G18-G17+G16 -> 903378000 | H20: =H15-H14+H18-H17+H16 -> 1016436000 | I20: =I15-I14+I18-I17+I16 -> 858306000 | J20: =J15-J14+J18-J17+J16 -> 901221300 | ... N20: =N15-N14+N18-N17+N16 -> 1.0954401e+09
B22: ROE ( net income / equity ) | C22: =C13/C18 -> 0.12306929 | D22: =D13/D18 -> 0.2457302 | E22: =E13/E18 -> 0.23629267 | F22: =F13/F18 -> 0.27459503 | G22: =G13/G18 -> 0.29445908 | H22: =H13/H18 -> 0.28479164 | I22: =I13/I18 -> 0.33915153 | J22: =J13/J18 -> 0.21271598 | ... N22: =N13/N18 -> 0.21271598
B23: ROCE sin goodwill (EBIT / Capital empleado) | C23: =C10/C20 -> 0.42856414 | D23: =D10/D20 -> 0.68951395 | E23: =E10/E20 -> 0.43910876 | F23: =F10/F20 -> 0.92486115 | G23: =G10/G20 -> 0.62863275 | H23: =H10/H20 -> 0.64496732 | I23: =I10/I20 -> 1.0913276 | J23: =J10/J20 -> 0.69938556 | ... N23: =N10/N20 -> 0.69938556
B24: ROCE con goodwill( EBIT / Capital empleado) | C24: =C10/C19 -> 0.41752028 | D24: =D10/D19 -> 0.66970399 | E24: =E10/E19 -> 0.43129705 | F24: =F10/F19 -> 0.90247203 | G24: =G10/G19 -> 0.61904601 | H24: =H10/H19 -> 0.63621065 | I24: =I10/I19 -> 1.0738247 | J24: =J10/J19 -> 0.68816872 | ... N24: =N10/N19 -> 0.68816872

Sheet 4. Valoración
C8: 2018 | D8: 2019 | E8: 2020 | F8: 2021 | G8: 2022 | H8: 2023 | I8: 2024 | J8: 2025 | K8: 2026 | L8: 2027 | M8: 2028 | N8: 2029
B9: Valuation ( millons ,except EPS ) | O9: Cotización actual | Q9: 82.82
B10: Market cap | I10: =$Q$9*'1.Income statement'!I27 -> 1.2943772e+10 | J10: =$Q$9*'1.Income statement'!J27 -> 1.2716355e+10 | K10: =$Q$9*'1.Income statement'!K27 -> 1.2477568e+10 | L10: =$Q$9*'1.Income statement'!L27 -> 1.2226841e+10 | M10: =$Q$9*'1.Income statement'!M27 -> 1.1963578e+10 | N10: =$Q$9*'1.Income statement'!N27 -> 1.1687151e+10
B11: Net DEBT (-) si es caja neta | C11: ='3.retornos capital'!C15-'3.retornos capital'!C14+'3.retornos capital'!C16 -> -397888000 | D11: ='3.retornos capital'!D15-'3.retornos capital'!D14+'3.retornos capital'!D16 -> -558188000 | E11: ='3.retornos capital'!E15-'3.retornos capital'!E14+'3.retornos capital'!E16 -> -353720000 | F11: ='3.retornos capital'!F15-'3.retornos capital'!F14+'3.retornos capital'!F16 -> -866319000 | G11: ='3.retornos capital'!G15-'3.retornos capital'!G14+'3.retornos capital'!G16 -> -621457000 | H11: ='3.retornos capital'!H15-'3.retornos capital'!H14+'3.retornos capital'!H16 -> -735307000 | I11: ='3.retornos capital'!I15-'3.retornos capital'!I14+'3.retornos capital'!I16 -> -1235172000 | J11: ='Datos Tweenvest'!I84-'2.Flujos de caja'!J31 -> -1.4450951e+09 | K11: ='Datos Tweenvest'!J84-'2.Flujos de caja'!K31 -> -2.2041927e+08 | L11: ='Datos Tweenvest'!K84-'2.Flujos de caja'!L31 -> -2.3144023e+08 | M11: ='Datos Tweenvest'!L84-'2.Flujos de caja'!M31 -> -2.4301224e+08 | N11: ='Datos Tweenvest'!M84-'2.Flujos de caja'!N31 -> -2.5516286e+08 | O11: Dividend yield | Q11: 0
B12: Deuda neta /EBITDA | C12: =C11/'1.Income statement'!C12 -> -1.4456038 | D12: =D11/'1.Income statement'!D12 -> -1.5043552 | E12: =E11/'1.Income statement'!E12 -> -0.93555929 | F12: =F11/'1.Income statement'!F12 -> -1.5412899 | G12: =G11/'1.Income statement'!G12 -> -1.0174959 | H12: =H11/'1.Income statement'!H12 -> -1.0453225 | I12: =I11/'1.Income statement'!I12 -> -1.2422778 | J12: =J11/'1.Income statement'!J12 -> -2.0920137 | ... N12: =N11/'1.Income statement'!N12 -> -0.30389836
B13: Deuda neta/equity | C13: =C11/'3.retornos capital'!C18 -> -0.42293461 | D13: =D11/'3.retornos capital'!D18 -> -0.53408476 | E13: =E11/'3.retornos capital'!E18 -> -0.31024804 | F13: =F11/'3.retornos capital'!F18 -> -0.59985044 | G13: =G11/'3.retornos capital'!G18 -> -0.40385164 | H13: =H11/'3.retornos capital'!H18 -> -0.41643159 | I13: =I11/'3.retornos capital'!I18 -> -0.58609288 | J13: =J11/'3.retornos capital'!J18 -> -0.65304957 | ... N13: =N11/'3.retornos capital'!N18 -> -0.094865865
B14: Enterprise Value ( EV ) | I14: =I10+I11 -> 1.17086e+10 | J14: =J10+J11 -> 1.127126e+10 | K14: =K10+K11 -> 1.2257149e+10 | L14: =L10+L11 -> 1.1995401e+10 | M14: =M10+M11 -> 1.1720565e+10 | N14: =N10+N11 -> 1.1431988e+10
B15: EBITDA | C15: ='1.Income statement'!C12 -> 275240000 | D15: ='1.Income statement'!D12 -> 371048000 | E15: ='1.Income statement'!E12 -> 378084000 | F15: ='1.Income statement'!F12 -> 562074000 | G15: ='1.Income statement'!G12 -> 610771000 | H15: ='1.Income statement'!H12 -> 703426000 | I15: ='1.Income statement'!I12 -> 994280000 | J15: ='1.Income statement'!J12 -> 6.9076751e+08 | ... N15: ='1.Income statement'!N12 -> 8.3963223e+08
B16: EBIT | C16: ='1.Income statement'!C15 -> 226668000 | D16: ='1.Income statement'!D15 -> 326107000 | E16: ='1.Income statement'!E15 -> 339172000 | F16: ='1.Income statement'!F15 -> 521544000 | G16: ='1.Income statement'!G15 -> 567893000 | H16: ='1.Income statement'!H15 -> 655568000 | I16: ='1.Income statement'!I15 -> 936693000 | J16: ='1.Income statement'!J15 -> 6.3030116e+08 | ... N16: ='1.Income statement'!N15 -> 7.66135e+08
B17: Net income | C17: ='1.Income statement'!C24 -> 115781000 | D17: ='1.Income statement'!D24 -> 256820000 | E17: ='1.Income statement'!E24 -> 269402000 | F17: ='1.Income statement'!F24 -> 396577000 | G17: ='1.Income statement'!G24 -> 453121000 | H17: ='1.Income statement'!H24 -> 502866000 | I17: ='1.Income statement'!I24 -> 714751000 | J17: ='1.Income statement'!J24 -> 4.7070672e+08 | ... N17: ='1.Income statement'!N24 -> 5.7214696e+08
B18: FCF | C18: ='2.Flujos de caja'!C16 -> 129540000 | D18: ='2.Flujos de caja'!D16 -> 272675000 | E18: ='2.Flujos de caja'!E16 -> 275859000 | F18: ='2.Flujos de caja'!F16 -> 404889000 | G18: ='2.Flujos de caja'!G16 -> 444982000 | H18: ='2.Flujos de caja'!H16 -> 469699000 | I18: ='2.Flujos de caja'!I16 -> 682973000 | J18: ='2.Flujos de caja'!J16 -> 4.3733982e+08 | ... N18: ='2.Flujos de caja'!N16 -> 5.3158929e+08
C20: 3 YEARS | D20: 5 YEARS
B21: CAGR by PER | C21: =((L21/$Q$9)^(1/3)-1)+$Q$11 -> -0.15045343 | D21: =((N21/$Q$9)^(1/5)-1)+$Q$11 -> -0.066940898 | F21: PER+caja | I21: =IF(--I11<0,(I17*$Q$21-I11),IF(--I11>0,I17*$Q$21))/'1.Income statement'!I27 -> 71.929297 | J21: =IF(J11<0,J17*$Q$21-J11,IF(J11=0,J17*$Q$21,IF(J11>0,J17*$Q$21)))/'1.Income statement'!J27 -> 52.330859 | K21: =IF(K11<0,K17*$Q$21-K11,IF(K11=0,K17*$Q$21,IF(K11>0,K17*$Q$21)))/'1.Income statement'!K27 -> 47.390558 | L21: =IF(L11<0,L17*$Q$21-L11,IF(L11=0,L17*$Q$21,IF(L11>0,L17*$Q$21)))/'1.Income statement'!L27 -> 50.78048 | M21: =IF(M11<0,M17*$Q$21-M11,IF(M11=0,M17*$Q$21,IF(M11>0,M17*$Q$21)))/'1.Income statement'!M27 -> 54.49282 | N21: =IF(N11<0,N17*$Q$21-N11,IF(N11=0,N17*$Q$21,IF(N11>0,N17*$Q$21)))/'1.Income statement'!N27 -> 58.570778 | O21: Multiple PER | Q21: 14
B22: CAGR by P/FCF | C22: =((L22/$Q$9)^(1/3)-1)+$Q$11 -> -0.17037091 | D22: =((N22/$Q$9)^(1/5)-1)+$Q$11 -> -0.080128374 | F22: P/FCF +caja | I22: =IF(--I11<0,(I18*$Q$22-I11),IF(--I11>0,I18*$Q$22))/'1.Income statement'!I27 -> 69.082681 | J22: =IF(J11<0,J18*$Q$22-J11,IF(J11=0,J18*$Q$22,IF(J11>0,J18*$Q$22)))/'1.Income statement'!J27 -> 49.288458 | K22: =IF(K11<0,K18*$Q$22-K11,IF(K11=0,K18*$Q$22,IF(K11>0,K18*$Q$22)))/'1.Income statement'!K27 -> 44.134902 | L22: =IF(L11<0,L18*$Q$22-L11,IF(L11=0,L18*$Q$22,IF(L11>0,L18*$Q$22)))/'1.Income statement'!L27 -> 47.291942 | M22: =IF(M11<0,M18*$Q$22-M11,IF(M11=0,M18*$Q$22,IF(M11>0,M18*$Q$22)))/'1.Income statement'!M27 -> 50.74925 | N22: =IF(N11<0,N18*$Q$22-N11,IF(N11=0,N18*$Q$22,IF(N11>0,N18*$Q$22)))/'1.Income statement'!N27 -> 54.547059 | O22: Multiple P/FCF | Q22: 14
B23: CAGR by EV/EBITDA | C23: =((L23/$Q$9)^(1/3)-1)+$Q$11 -> -0.23089851 | D23: =((N23/$Q$9)^(1/5)-1)+$Q$11 -> -0.12100373 | F23: EV/EBITDA | I23: =((I15*$Q$23)-I11)/'1.Income statement'!I27 -> 52.436092 | J23: =((J15*$Q$23)-J11)/'1.Income statement'!J27 -> 40.903884 | K23: =((K15*$Q$23)-K11)/'1.Income statement'!K27 -> 35.162618 | L23: =((L15*$Q$23)-L11)/'1.Income statement'!L27 -> 37.677856 | M23: =((M15*$Q$23)-M11)/'1.Income statement'!M27 -> 40.432321 | N23: =((N15*$Q$23)-N11)/'1.Income statement'!N27 -> 43.458065 | O23: Multiple EV/EBITDA | Q23: 7
B24: CAGR by EV/EBIT | C24: =((L24/$Q$9)^(1/3)-1)+$Q$11 -> -0.19050896 | D24: =((N24/$Q$9)^(1/5)-1)+$Q$11 -> -0.0935913 | F24: EV/EBIT | I24: =((I16*$Q$24)-I11)/'1.Income statement'!I27 -> 61.843577 | J24: =((J16*$Q$24)-J11)/'1.Income statement'!J27 -> 46.357359 | K24: =((K16*$Q$24)-K11)/'1.Income statement'!K27 -> 40.99835 | L24: =((L16*$Q$24)-L11)/'1.Income statement'!L27 -> 43.931027 | M24: =((M16*$Q$24)-M11)/'1.Income statement'!M27 -> 47.142634 | N24: =((N16*$Q$24)-N11)/'1.Income statement'!N27 -> 50.670542 | O24: Multiple EV/EBIT | Q24: 9
M27: 3Y | N27: 5Y | R27: 3Y Value | S27: 5Y
L29: Bull case | M29: 244 | N29: 398 | P29: 0.2 | R29: =M29*P29 -> 48.8 | S29: =N29*P29 -> 79.6
L30: Mid Case | M30: 119 | N30: 158 | P30: 0.6 | R30: =M30*P30 -> 71.4 | S30: =N30*P30 -> 94.8
L31: Bear | M31: 45 | N31: 52 | P31: 0.2 | R31: =M31*P31 -> 9 | S31: =N31*P31 -> 10.4
R32: =SUM(R29:R31) -> 129.2 | S32: =S29+S30+S31 -> 184.8

Sheet INSTRUCCIONES
B3: PAUTAS PARA RELLENAR LA HOJA DE EXCEL
B4: La hoja excel consta de 4 pestañas y en todas hay que rellenar datos, en concreto todas aquellas casillas que esten en sombredo gris.
B6: En las siguientes pestañas hay que rellenar:
B8: Hoja de Income Statement
B9: Ventas ( sales )
B10: EBIT ( operating income)
B11: D&A ( depreciacion y amortizacion)
B12: intereses ( o ingresos financieros)
B13: impuestos (income tax )
B14: numero de acciones diluidas / intereses minoritarios
B15: En la parte derecha hemos de rellenar las 3 casillas de estimaciones futuras ( crecimiento, margenes EBIT y tasa impositiva ) casillas P11, P16, P21. La linea de intereses minoritarios hemos de rellenarla, aunque si supone poco % sobre el total del beneficio lo podemos dejar a cero.
B17: Hoja de Flujos de Caja
... B28: Ante todo piensa si tiene sentido los datos que introduces, usa el sentido común. No pasa nada si los datos no son exactos, la valoración no es una ciencia exacta sino mas bien una opinion. Si salen resultados muy extraños analiza todos los datos introducidos. Practica mucho te llevará varias repeticiones usar correctamente la plantilla.
